[2024-02-16T18:15:56.552+0000] {taskinstance.py:1956} INFO - Dependencies all met for dep_context=non-requeueable deps ti=<TaskInstance: mlb_dag.player_lookup scheduled__2024-02-15T00:00:00+00:00 [queued]>
[2024-02-16T18:15:56.558+0000] {taskinstance.py:1956} INFO - Dependencies all met for dep_context=requeueable deps ti=<TaskInstance: mlb_dag.player_lookup scheduled__2024-02-15T00:00:00+00:00 [queued]>
[2024-02-16T18:15:56.559+0000] {taskinstance.py:2170} INFO - Starting attempt 2 of 2
[2024-02-16T18:15:56.570+0000] {taskinstance.py:2191} INFO - Executing <Task(PythonOperator): player_lookup> on 2024-02-15 00:00:00+00:00
[2024-02-16T18:15:56.575+0000] {standard_task_runner.py:60} INFO - Started process 111 to run task
[2024-02-16T18:15:56.577+0000] {standard_task_runner.py:87} INFO - Running: ['***', 'tasks', 'run', 'mlb_dag', 'player_lookup', 'scheduled__2024-02-15T00:00:00+00:00', '--job-id', '6', '--raw', '--subdir', 'DAGS_FOLDER/mlb_dag.py', '--cfg-path', '/tmp/tmptj2ho2tv']
[2024-02-16T18:15:56.579+0000] {standard_task_runner.py:88} INFO - Job 6: Subtask player_lookup
[2024-02-16T18:15:56.609+0000] {task_command.py:423} INFO - Running <TaskInstance: mlb_dag.player_lookup scheduled__2024-02-15T00:00:00+00:00 [running]> on host 9f908554d9a1
[2024-02-16T18:15:56.789+0000] {taskinstance.py:2480} INFO - Exporting env vars: AIRFLOW_CTX_DAG_EMAIL='***@example.com' AIRFLOW_CTX_DAG_OWNER='troy' AIRFLOW_CTX_DAG_ID='mlb_dag' AIRFLOW_CTX_TASK_ID='player_lookup' AIRFLOW_CTX_EXECUTION_DATE='2024-02-15T00:00:00+00:00' AIRFLOW_CTX_TRY_NUMBER='2' AIRFLOW_CTX_DAG_RUN_ID='scheduled__2024-02-15T00:00:00+00:00'
[2024-02-16T18:15:56.791+0000] {taskinstance.py:2698} ERROR - Task failed with exception
Traceback (most recent call last):
  File "/home/airflow/.local/lib/python3.8/site-packages/airflow/models/taskinstance.py", line 433, in _execute_task
    result = execute_callable(context=context, **execute_callable_kwargs)
  File "/home/airflow/.local/lib/python3.8/site-packages/airflow/operators/python.py", line 199, in execute
    return_value = self.execute_callable()
  File "/home/airflow/.local/lib/python3.8/site-packages/airflow/operators/python.py", line 216, in execute_callable
    return self.python_callable(*self.op_args, **self.op_kwargs)
  File "/opt/airflow/dags/mlbapi.py", line 5, in player_lookup
    from pybaseball import  playerid_lookup
ModuleNotFoundError: No module named 'pybaseball'
[2024-02-16T18:15:56.798+0000] {taskinstance.py:1138} INFO - Marking task as FAILED. dag_id=mlb_dag, task_id=player_lookup, execution_date=20240215T000000, start_date=20240216T181556, end_date=20240216T181556
[2024-02-16T18:15:56.806+0000] {standard_task_runner.py:107} ERROR - Failed to execute job 6 for task player_lookup (No module named 'pybaseball'; 111)
[2024-02-16T18:15:56.829+0000] {local_task_job_runner.py:234} INFO - Task exited with return code 1
[2024-02-16T18:15:56.841+0000] {taskinstance.py:3280} INFO - 0 downstream tasks scheduled from follow-on schedule check
